Workbook

Sheet Final Recommendation
A1: FINAL RECOMMENDATION – Amber straight-sided jars & launch plan
A2: Updated Oct 9, 2026 with LIVE supplier prices. Volumes: Balance 2,000 · 60ct 500 · 90ct 500 (edit on Inputs). Blue cells are editable; replace with written quotes and everything recalculates.
A3: ⚠ CONFIRMED: Canada charges a 50% surtax on US-MADE glass jars (SOR/2026-186, tariff 7010.90.00, since Sept 8, 2026). It's based on where the jar was made. China-made jars: no duty, no surtax.
A5: 1. THE DECISION
A6: Bottle style | B6: ="Sticking with your CURRENT packer style is cheaper: ~CAD "&TEXT('Packer vs Straight-Sided'!H51,"#,##0")&" less in regular and ~CAD "&TEXT('Packer vs Straight-Sided'!H53,"#,##0")&" less in frosted (see the Packer vs Straight-Sided tab). Packer sizes: Balance 120cc · 60ct 150cc · 90ct 250cc. The rest of this tab covers the straight-sided route if you prefer that look." -> Sticking with your CURRENT packer style is cheaper: ~CAD 960 less in regular and ~CAD 975 less in frosted (see the Packer vs Straight-Sided tab). Packer sizes: Balance 120cc · 60ct 150cc · 90ct 250cc. The rest of this tab covers the straight-sided route if you prefer that look.
A7: Launch order | B7: 1st: 90ct androgen-balancing (berberine). 2nd: 60ct liver booster, positioned as an add-on to Balance AND the 90ct. Balance moves to the new jar when its jars arrive.
A8: Jar per SKU | B8: Balance → 4 oz (looks like today) · 60ct → 6 oz / 175–190 ml · 90ct → 8 oz (237 ml; ~270 ml brim-full). The 8 oz works whether the 90ct ends up size 0 (~61% full) or 00 (fits).
A9: 90ct (launch first) | B9: Buy 500 × 8 oz LOCALLY now. Cheapest landed: SKS Bottle (free UPS to Ontario, induction-lined caps). Get the jar's country of origin first – if US-made, Uline's 8 oz (Canadian stock) costs about the same.
A10: Balance + 60ct | B10: ="It depends on where Burch's jars are made (ask them). NOT US-made → buy both from Burch in ONE shipment (Plan B): within CAD "&TEXT(ABS(D58),"#,##0")&" of China, with no 3-month wait and no quality risk. US-made (50% surtax) → a China order saves ~CAD "&TEXT(E58,"#,##0")&" (Plan A), if the RFQ meets the table 3 targets." -> It depends on where Burch's jars are made (ask them). NOT US-made → buy both from Burch in ONE shipment (Plan B): within CAD 14 of China, with no 3-month wait and no quality risk. US-made (50% surtax) → a China order saves ~CAD 906 (Plan A), if the RFQ meets the table 3 targets.
A11: Finish | B11: ="Cost-first pick = REGULAR. Frosted adds ~CAD "&TEXT(D59,"#,##0")&" (Plan E vs A), mostly from spray-frosting just 500 × 8 oz locally. Cheaper frosted route: Balance + 60ct frosted from China by sea, and the 90ct frosted jars flown from China (DDP air, ~5–7 weeks incl. production) – see the Packer vs Straight-Sided tab. Frosting everything locally (Plan F) costs far more." -> Cost-first pick = REGULAR. Frosted adds ~CAD 1,374 (Plan E vs A), mostly from spray-frosting just 500 × 8 oz locally. Cheaper frosted route: Balance + 60ct frosted from China by sea, and the 90ct frosted jars flown from China (DDP air, ~5–7 weeks incl. production) – see the Packer vs Straight-Sided tab. Frosting everything locally (Plan F) costs far more.
A12: Cheaper but less certain | B12: ="Plan D (everything from Burch in one shipment, with a 9 oz for the 90ct) saves another ~CAD "&TEXT(D53-D55,"#,##0")&" vs Plan B, but a 9 oz looks only ~54% full if the 90ct ends up size 0. Your call on looks vs savings." -> Plan D (everything from Burch in one shipment, with a 9 oz for the 90ct) saves another ~CAD 544 vs Plan B, but a 9 oz looks only ~54% full if the 90ct ends up size 0. Your call on looks vs savings.
A13: Future reorders | B13: Once volumes grow, move the 90ct to a China 250 ml jar on the same order as Balance + 60ct so all three jars match and freight is shared.
A15: 2. LOCAL JAR FOR THE 90ct – 500 × 8 oz (cheapest landed highlighted; live prices)
A16: Option | B16: Item | C16: Ships from | D16: Currency | E16: Jar price | F16: Cap price (per jar needed) | G16: Notes | H16: FX | I16: Goods (CAD/jar) | J16: Freight & brokerage (CAD/jar) | K16: LANDED regular (CAD/jar) | L16: Landed if jar is US-made (+50% surtax) | M16: LANDED frosted (spray, CAD/jar) | N16: Capacity (ml, nominal) | O16: Looks full if size 0 | P16: Fits size 00? | Q16: Total regular (CAD) | R16: Total frosted (CAD)
A17: SKS Bottle (US) | B17: 40530080.03S 8 oz amber SS 70/400 (case 36) | C17: US | D17: USD | E17: 0.88 | F17: =159.6/Inputs!$B$7 -> 0.3192 | G17: Live $31.68/36. Cap 2101-79B black PP + foam INDUCTION liner, $159.60 per case of 760 (whole case spread over the jars needed). FREE UPS Ground to Ontario on US$500+ → only brokerage applies. Jar origin not stated ('kit assembled in USA'). | H17: =IF(D17="USD",Inputs!$B$10,1) -> 1.424 | I17: =(E17+F17)*H17*(1+Inputs!$B$33) -> 1.7076608 | J17: =Inputs!$B$25/Inputs!$B$7 -> 0.25 | K17: =I17+J17 -> 1.9576608 | L17: =K17+E17*H17*Inputs!$B$34 -> 2.5842208 | M17: =K17+Inputs!$B$37+(Inputs!$B$38+Inputs!$B$39)/Inputs!$B$7 -> 4.3076608 | N17: 237 | O17: ='Capsule Sizing'!$D$30/N17 -> 0.60773326 | P17: =IF('Capsule Sizing'!$E$29/N17>1,"No",IF('Capsule Sizing'!$E$29/N17>'Capsule Sizing'!$B$13,"Yes – snug, test","Yes")) -> Yes – snug, test | Q17: =K17*Inputs!$B$7 -> 978.8304 | R17: =M17*Inputs!$B$7 -> 2153.8304
A18: Bottlestore (US) | B18: 55220042 8 oz amber SS 70-405 (fits 70-400); 272 ml brim-full | C18: US | D18: USD | E18: 0.46 | F18: 0.21 | G18: Live $0.46 (24/ctn). Cap 70400OV black ribbed F217 $0.21 (Made in USA). Freight to Canada extra. Jar origin not stated (their 4 oz is Made in USA). | H18: =IF(D18="USD",Inputs!$B$10,1) -> 1.424 | I18: =(E18+F18)*H18*(1+Inputs!$B$33) -> 0.95408 | J18: =(Inputs!$B$24*Inputs!$B$10+Inputs!$B$25)/Inputs!$B$7 -> 1.3892 | K18: =I18+J18 -> 2.34328 | L18: =K18+E18*H18*Inputs!$B$34 -> 2.6708 | M18: =K18+Inputs!$B$37+(Inputs!$B$38+Inputs!$B$39)/Inputs!$B$7 -> 4.69328 | N18: 237 | O18: ='Capsule Sizing'!$D$30/N18 -> 0.60773326 | P18: =IF('Capsule Sizing'!$E$29/N18>1,"No",IF('Capsule Sizing'!$E$29/N18>'Capsule Sizing'!$B$13,"Yes – snug, test","Yes")) -> Yes – snug, test | Q18: =K18*Inputs!$B$7 -> 1171.64 | R18: =M18*Inputs!$B$7 -> 2346.64
A19: Uline Canada (metal cap) | B19: S-25207 8 oz amber SS, black metal cap, plastisol liner | C19: Canada | D19: CAD | E19: 2.2 | F19: 0 | G19: Live CAD 2.20 at 3+ cases, cap included. Canadian stock (any surtax is already in Uline's price). Metal/plastisol cap can't be induction sealed – use a shrink band. Phenolic version S-24533 CAD 2.35. | H19: =IF(D19="USD",Inputs!$B$10,1) -> 1 | I19: =(E19+F19)*H19*(1+Inputs!$B$33) -> 2.2 | J19: =Inputs!$B$26/Inputs!$B$7 -> 0.3 | K19: =I19+J19 -> 2.5 | L19: =K19 -> 2.5 | M19: =K19+Inputs!$B$37+(Inputs!$B$38+Inputs!$B$39)/Inputs!$B$7 -> 4.85 | N19: 237 | O19: ='Capsule Sizing'!$D$30/N19 -> 0.60773326 | P19: =IF('Capsule Sizing'!$E$29/N19>1,"No",IF('Capsule Sizing'!$E$29/N19>'Capsule Sizing'!$B$13,"Yes – snug, test","Yes")) -> Yes – snug, test | Q19: =K19*Inputs!$B$7 -> 1250 | R19: =M19*Inputs!$B$7 -> 2425
A20: Voyageur (Canada) | B20: GJ-AMB-70-400-8OZ 8 oz amber glass 70-400 | C20: Canada | D20: CAD | E20: 1.95 | F20: 0.54 | G20: Live single-unit price ($2.49 with ribbed cap). No bulk pricing; shape not confirmed straight-sided. Ask for a 500-unit quote. | H20: =IF(D20="USD",Inputs!$B$10,1) -> 1 | I20: =(E20+F20)*H20*(1+Inputs!$B$33) -> 2.49 | J20: =Inputs!$B$26/Inputs!$B$7 -> 0.3 | K20: =I20+J20 -> 2.79 | L20: =K20 -> 2.79 | M20: =K20+Inputs!$B$37+(Inputs!$B$38+Inputs!$B$39)/Inputs!$B$7 -> 5.14 | N20: 237 | O20: ='Capsule Sizing'!$D$30/N20 -> 0.60773326 | P20: =IF('Capsule Sizing'!$E$29/N20>1,"No",IF('Capsule Sizing'!$E$29/N20>'Capsule Sizing'!$B$13,"Yes – snug, test","Yes")) -> Yes – snug, test | Q20: =K20*Inputs!$B$7 -> 1395 | R20: =M20*Inputs!$B$7 -> 2570
A21: Alt: Richards 9 oz (Canada, China-made) | B21: RP-1001A 9 oz amber SS 70-400 | C21: Canada | D21: CAD | E21: 0.99 | F21: 0.25 | G21: Live list price (member price may be lower); 70 mm black PP cap 32110979. No surtax risk. BUT a 9 oz looks only ~54% full if the 90ct is size 0. | H21: =IF(D21="USD",Inputs!$B$10,1) -> 1 | I21: =(E21+F21)*H21*(1+Inputs!$B$33) -> 1.24 | J21: =Inputs!$B$26/Inputs!$B$7 -> 0.3 | K21: =I21+J21 -> 1.54 | L21: =K21 -> 1.54 | M21: =K21+Inputs!$B$37+(Inputs!$B$38+Inputs!$B$39)/Inputs!$B$7 -> 3.89 | N21: 266 | O21: ='Capsule Sizing'!$D$30/N21 -> 0.54147662 | P21: =IF('Capsule Sizing'!$E$29/N21>1,"No",IF('Capsule Sizing'!$E$29/N21>'Capsule Sizing'!$B$13,"Yes – snug, test","Yes")) -> Yes | Q21: =K21*Inputs!$B$7 -> 770 | R21: =M21*Inputs!$B$7 -> 1945
A22: Alt: Burch 9 oz (US) | B22: 1SSA092SGC 9 oz amber SS 70-400 | C22: US | D22: USD | E22: 0.441 | F22: 0.17 | G22: Live $5.29/12 at 40–175 cases; cap 2BP0701PX $0.17. Same ~54% look issue if size 0. Jar origin not stated. | H22: =IF(D22="USD",Inputs!$B$10,1) -> 1.424 | I22: =(E22+F22)*H22*(1+Inputs!$B$33) -> 0.870064 | J22: =(Inputs!$B$24*Inputs!$B$10+Inputs!$B$25)/Inputs!$B$7 -> 1.3892 | K22: =I22+J22 -> 2.259264 | L22: =K22+E22*H22*Inputs!$B$34 -> 2.573256 | M22: =K22+Inputs!$B$37+(Inputs!$B$38+Inputs!$B$39)/Inputs!$B$7 -> 4.609264 | N22: 266 | O22: ='Capsule Sizing'!$D$30/N22 -> 0.54147662 | P22: =IF('Capsule Sizing'!$E$29/N22>1,"No",IF('Capsule Sizing'!$E$29/N22>'Capsule Sizing'!$B$13,"Yes – snug, test","Yes")) -> Yes | Q22: =K22*Inputs!$B$7 -> 1129.632 | R22: =M22*Inputs!$B$7 -> 2304.632
A23: Cheapest 8 oz (used in table 4) → | K23: =MIN(K17:K20) -> 1.9576608 | L23: =MIN(L17:L20) -> 2.5 | M23: =MIN(M17:M20) -> 4.3076608
A25: 3. BALANCE (2,000 × 4 oz) + 60ct (500 × 6 oz) – China order vs buying locally
A26: Go with China ONLY IF the RFQ comes back ≤ US$0.50/jar including a PP cap with induction liner (both sizes, one supplier, matching style) AND LCL door-to-door ≤ CAD 1,100. Otherwise buy locally.
A27: Option / SKU | B27: Source | C27: Jar | D27: Jar + cap (native) | E27: FX | F27: Goods (CAD/jar) | G27: Frosting (CAD/jar) | H27: Freight, brokerage, samples/QC (CAD/jar) | I27: LANDED (CAD/jar) | J27: Surtax if jar is US-made (CAD/jar) | K27: Landed if US-made | L27: Qty | M27: Total (CAD) | N27: Total if US-made (CAD)
A28: 3a. CHINA – regular amber (one LCL shipment)
A29: Balance – 30ct | B29: China direct | C29: ='Regular Finish – Top 3'!B25 -> 120 ml | D29: ='Regular Finish – Top 3'!I25+'Regular Finish – Top 3'!K25 -> 0.49 | E29: ='Regular Finish – Top 3'!L25 -> 1.424 | F29: =D29*E29*(1+Inputs!$B$33) -> 0.69776 | G29: 0 | H29: =(Inputs!$B$28+Inputs!$B$30)/(Inputs!$B$5+Inputs!$B$6) -> 0.664 | I29: =F29+G29+H29 -> 1.36176 | J29: 0 | K29: =I29+J29 -> 1.36176 | L29: =Inputs!$B$5 -> 2000 | M29: =I29*L29 -> 2723.52 | N29: =K29*L29 -> 2723.52
A30: New A – 60ct | B30: China direct | C30: ='Regular Finish – Top 3'!B26 -> 180–190 ml | D30: ='Regular Finish – Top 3'!I26+'Regular Finish – Top 3'!K26 -> 0.55 | E30: ='Regular Finish – Top 3'!L26 -> 1.424 | F30: =D30*E30*(1+Inputs!$B$33) -> 0.7832 | G30: 0 | H30: =(Inputs!$B$28+Inputs!$B$30)/(Inputs!$B$5+Inputs!$B$6) -> 0.664 | I30: =F30+G30+H30 -> 1.4472 | J30: 0 | K30: =I30+J30 -> 1.4472 | L30: =Inputs!$B$6 -> 500 | M30: =I30*L30 -> 723.6 | N30: =K30*L30 -> 723.6
A31: Subtotal | M31: =SUM(M29:M30) -> 3447.12 | N31: =SUM(N29:N30) -> 3447.12
A32: 3b. LOCAL – Burch 4 oz + 6 oz, one US shipment
A33: Balance – 30ct | B33: Burch (US) | C33: ='Regular Finish – Top 3'!B7 -> 4 oz | D33: ='Regular Finish – Top 3'!I7+'Regular Finish – Top 3'!K7 -> 0.61708333 | E33: ='Regular Finish – Top 3'!L7 -> 1.424 | F33: =D33*E33*(1+Inputs!$B$33) -> 0.87872667 | G33: 0 | H33: =(Inputs!$B$18*Inputs!$B$10+Inputs!$B$19)/(Inputs!$B$5+Inputs!$B$6) -> 0.44024 | I33: =F33+G33+H33 -> 1.3189667 | J33: ='Regular Finish – Top 3'!I7*E33*Inputs!$B$34 -> 0.33968333 | K33: =I33+J33 -> 1.65865 | L33: =Inputs!$B$5 -> 2000 | M33: =I33*L33 -> 2637.9333 | N33: =K33*L33 -> 3317.3
A34: New A – 60ct | B34: Burch (US) | C34: ='Regular Finish – Top 3'!B8 -> 6 oz | D34: ='Regular Finish – Top 3'!I8+'Regular Finish – Top 3'!K8 -> 0.8075 | E34: ='Regular Finish – Top 3'!L8 -> 1.424 | F34: =D34*E34*(1+Inputs!$B$33) -> 1.14988 | G34: 0 | H34: =(Inputs!$B$18*Inputs!$B$10+Inputs!$B$19)/(Inputs!$B$5+Inputs!$B$6) -> 0.44024 | I34: =F34+G34+H34 -> 1.59012 | J34: ='Regular Finish – Top 3'!I8*E34*Inputs!$B$34 -> 0.48238 | K34: =I34+J34 -> 2.0725 | L34: =Inputs!$B$6 -> 500 | M34: =I34*L34 -> 795.06 | N34: =K34*L34 -> 1036.25
A35: Subtotal | M35: =SUM(M33:M34) -> 3432.9933 | N35: =SUM(N33:N34) -> 4353.55
A36: 3c. LOCAL – Richards 4 oz (Canada, China-made) + Burch 6 oz (small US shipment)
A37: Balance – 30ct | B37: Richards (Canada) | C37: ='Regular Finish – Top 3'!B34 -> 4 oz | D37: ='Regular Finish – Top 3'!I34+'Regular Finish – Top 3'!K34 -> 1.46 | E37: ='Regular Finish – Top 3'!L34 -> 1 | F37: =D37*E37*(1+Inputs!$B$33) -> 1.46 | G37: 0 | H37: =Inputs!$B$20/Inputs!$B$5 -> 0.15 | I37: =F37+G37+H37 -> 1.61 | J37: 0 | K37: =I37+J37 -> 1.61 | L37: =Inputs!$B$5 -> 2000 | M37: =I37*L37 -> 3220 | N37: =K37*L37 -> 3220
A38: New A – 60ct | B38: Burch (US) | C38: ='Regular Finish – Top 3'!B8 -> 6 oz | D38: ='Regular Finish – Top 3'!I8+'Regular Finish – Top 3'!K8 -> 0.8075 | E38: ='Regular Finish – Top 3'!L8 -> 1.424 | F38: =D38*E38*(1+Inputs!$B$33) -> 1.14988 | G38: 0 | H38: =(Inputs!$B$24*Inputs!$B$10+Inputs!$B$25)/Inputs!$B$6 -> 1.3892 | I38: =F38+G38+H38 -> 2.53908 | J38: ='Regular Finish – Top 3'!I8*E38*Inputs!$B$34 -> 0.48238 | K38: =I38+J38 -> 3.02146 | L38: =Inputs!$B$6 -> 500 | M38: =I38*L38 -> 1269.54 | N38: =K38*L38 -> 1510.73
A39: Subtotal | M39: =SUM(M37:M38) -> 4489.54 | N39: =SUM(N37:N38) -> 4730.73
A40: 3d. CHINA – frosted amber (one LCL shipment)
A41: Balance – 30ct | B41: China direct (frosted) | C41: ='Frosted Finish – Top 3'!B7 -> 120 ml | D41: ='Frosted Finish – Top 3'!I7+'Frosted Finish – Top 3'!K7 -> 0.53 | E41: ='Frosted Finish – Top 3'!L7 -> 1.424 | F41: =D41*E41*(1+Inputs!$B$33) -> 0.75472 | G41: 0 | H41: =(Inputs!$B$28+Inputs!$B$30)/(Inputs!$B$5+Inputs!$B$6) -> 0.664 | I41: =F41+G41+H41 -> 1.41872 | J41: 0 | K41: =I41+J41 -> 1.41872 | L41: =Inputs!$B$5 -> 2000 | M41: =I41*L41 -> 2837.44 | N41: =K41*L41 -> 2837.44
A42: New A – 60ct | B42: China direct (frosted) | C42: ='Frosted Finish – Top 3'!B8 -> 180–190 ml | D42: ='Frosted Finish – Top 3'!I8+'Frosted Finish – Top 3'!K8 -> 0.67 | E42: ='Frosted Finish – Top 3'!L8 -> 1.424 | F42: =D42*E42*(1+Inputs!$B$33) -> 0.95408 | G42: 0 | H42: =(Inputs!$B$28+Inputs!$B$30)/(Inputs!$B$5+Inputs!$B$6) -> 0.664 | I42: =F42+G42+H42 -> 1.61808 | J42: 0 | K42: =I42+J42 -> 1.61808 | L42: =Inputs!$B$6 -> 500 | M42: =I42*L42 -> 809.04 | N42: =K42*L42 -> 809.04
A43: Subtotal | M43: =SUM(M41:M42) -> 3646.48 | N43: =SUM(N41:N42) -> 3646.48
...

Sheet Packer vs Straight-Sided
A1: Current bottle style (amber wide-mouth PACKER) vs STRAIGHT-SIDED jars
A2: Live prices Oct 9, 2026. Same volumes as everywhere else (Inputs). Tamper method = cotton + outer shrink band (no heat seal); shrink bands cost about the same for both styles (~CAD 0.02/unit), so they're left out.
A4: 1. PACKER SIZES THAT FIT (standard sizes are 120 / 150 / 200 / 250cc – nobody stocks 175 or 225cc)
A5: SKU / scenario | B5: 120cc (38-400) | C5: 150cc (45-400) | D5: 200cc (45-400) | E5: 250cc (45-400) | F5: Recommended packer
A6: Capacity nominal / brim-full (cc) | B6: 120 / 135 | C6: 150 / 171 | D6: 200 / 226 | E6: 250 / 275
A7: Balance – 30ct (current) | B7: =IF('Capsule Sizing'!$E$26/135>1,"Too small",IF('Capsule Sizing'!$D$26/120<'Capsule Sizing'!$B$12,"Looks < half ("&TEXT('Capsule Sizing'!$D$26/120,"0%")&")",IF('Capsule Sizing'!$E$26/120>'Capsule Sizing'!$B$13,"Tight – test ("&TEXT('Capsule Sizing'!$D$26/120,"0%")&" full)","OK ("&TEXT('Capsule Sizing'!$D$26/120,"0%")&" full)"))) -> Looks < half (40%) | C7: =IF('Capsule Sizing'!$E$26/171>1,"Too small",IF('Capsule Sizing'!$D$26/150<'Capsule Sizing'!$B$12,"Looks < half ("&TEXT('Capsule Sizing'!$D$26/150,"0%")&")",IF('Capsule Sizing'!$E$26/150>'Capsule Sizing'!$B$13,"Tight – test ("&TEXT('Capsule Sizing'!$D$26/150,"0%")&" full)","OK ("&TEXT('Capsule Sizing'!$D$26/150,"0%")&" full)"))) -> Looks < half (32%) | D7: =IF('Capsule Sizing'!$E$26/226>1,"Too small",IF('Capsule Sizing'!$D$26/200<'Capsule Sizing'!$B$12,"Looks < half ("&TEXT('Capsule Sizing'!$D$26/200,"0%")&")",IF('Capsule Sizing'!$E$26/200>'Capsule Sizing'!$B$13,"Tight – test ("&TEXT('Capsule Sizing'!$D$26/200,"0%")&" full)","OK ("&TEXT('Capsule Sizing'!$D$26/200,"0%")&" full)"))) -> Looks < half (24%) | E7: =IF('Capsule Sizing'!$E$26/275>1,"Too small",IF('Capsule Sizing'!$D$26/250<'Capsule Sizing'!$B$12,"Looks < half ("&TEXT('Capsule Sizing'!$D$26/250,"0%")&")",IF('Capsule Sizing'!$E$26/250>'Capsule Sizing'!$B$13,"Tight – test ("&TEXT('Capsule Sizing'!$D$26/250,"0%")&" full)","OK ("&TEXT('Capsule Sizing'!$D$26/250,"0%")&" full)"))) -> Looks < half (19%) | F7: 120cc (as today)
A8: New A – 60ct (if size 0) | B8: =IF('Capsule Sizing'!$E$28/135>1,"Too small",IF('Capsule Sizing'!$D$28/120<'Capsule Sizing'!$B$12,"Looks < half ("&TEXT('Capsule Sizing'!$D$28/120,"0%")&")",IF('Capsule Sizing'!$E$28/120>'Capsule Sizing'!$B$13,"Tight – test ("&TEXT('Capsule Sizing'!$D$28/120,"0%")&" full)","OK ("&TEXT('Capsule Sizing'!$D$28/120,"0%")&" full)"))) -> Tight – test (80% full) | C8: =IF('Capsule Sizing'!$E$28/171>1,"Too small",IF('Capsule Sizing'!$D$28/150<'Capsule Sizing'!$B$12,"Looks < half ("&TEXT('Capsule Sizing'!$D$28/150,"0%")&")",IF('Capsule Sizing'!$E$28/150>'Capsule Sizing'!$B$13,"Tight – test ("&TEXT('Capsule Sizing'!$D$28/150,"0%")&" full)","OK ("&TEXT('Capsule Sizing'!$D$28/150,"0%")&" full)"))) -> OK (64% full) | D8: =IF('Capsule Sizing'!$E$28/226>1,"Too small",IF('Capsule Sizing'!$D$28/200<'Capsule Sizing'!$B$12,"Looks < half ("&TEXT('Capsule Sizing'!$D$28/200,"0%")&")",IF('Capsule Sizing'!$E$28/200>'Capsule Sizing'!$B$13,"Tight – test ("&TEXT('Capsule Sizing'!$D$28/200,"0%")&" full)","OK ("&TEXT('Capsule Sizing'!$D$28/200,"0%")&" full)"))) -> Looks < half (48%) | E8: =IF('Capsule Sizing'!$E$28/275>1,"Too small",IF('Capsule Sizing'!$D$28/250<'Capsule Sizing'!$B$12,"Looks < half ("&TEXT('Capsule Sizing'!$D$28/250,"0%")&")",IF('Capsule Sizing'!$E$28/250>'Capsule Sizing'!$B$13,"Tight – test ("&TEXT('Capsule Sizing'!$D$28/250,"0%")&" full)","OK ("&TEXT('Capsule Sizing'!$D$28/250,"0%")&" full)"))) -> Looks < half (38%) | F8: 150cc
A9: New A – 60ct (if size 00) | B9: =IF('Capsule Sizing'!$E$27/135>1,"Too small",IF('Capsule Sizing'!$D$27/120<'Capsule Sizing'!$B$12,"Looks < half ("&TEXT('Capsule Sizing'!$D$27/120,"0%")&")",IF('Capsule Sizing'!$E$27/120>'Capsule Sizing'!$B$13,"Tight – test ("&TEXT('Capsule Sizing'!$D$27/120,"0%")&" full)","OK ("&TEXT('Capsule Sizing'!$D$27/120,"0%")&" full)"))) -> Too small | C9: =IF('Capsule Sizing'!$E$27/171>1,"Too small",IF('Capsule Sizing'!$D$27/150<'Capsule Sizing'!$B$12,"Looks < half ("&TEXT('Capsule Sizing'!$D$27/150,"0%")&")",IF('Capsule Sizing'!$E$27/150>'Capsule Sizing'!$B$13,"Tight – test ("&TEXT('Capsule Sizing'!$D$27/150,"0%")&" full)","OK ("&TEXT('Capsule Sizing'!$D$27/150,"0%")&" full)"))) -> Tight – test (85% full) | D9: =IF('Capsule Sizing'!$E$27/226>1,"Too small",IF('Capsule Sizing'!$D$27/200<'Capsule Sizing'!$B$12,"Looks < half ("&TEXT('Capsule Sizing'!$D$27/200,"0%")&")",IF('Capsule Sizing'!$E$27/200>'Capsule Sizing'!$B$13,"Tight – test ("&TEXT('Capsule Sizing'!$D$27/200,"0%")&" full)","OK ("&TEXT('Capsule Sizing'!$D$27/200,"0%")&" full)"))) -> OK (64% full) | E9: =IF('Capsule Sizing'!$E$27/275>1,"Too small",IF('Capsule Sizing'!$D$27/250<'Capsule Sizing'!$B$12,"Looks < half ("&TEXT('Capsule Sizing'!$D$27/250,"0%")&")",IF('Capsule Sizing'!$E$27/250>'Capsule Sizing'!$B$13,"Tight – test ("&TEXT('Capsule Sizing'!$D$27/250,"0%")&" full)","OK ("&TEXT('Capsule Sizing'!$D$27/250,"0%")&" full)"))) -> OK (51% full) | F9: 150cc – tight, pour-test (fits brim-full)
A10: New B – 90ct (if size 0) | B10: =IF('Capsule Sizing'!$E$30/135>1,"Too small",IF('Capsule Sizing'!$D$30/120<'Capsule Sizing'!$B$12,"Looks < half ("&TEXT('Capsule Sizing'!$D$30/120,"0%")&")",IF('Capsule Sizing'!$E$30/120>'Capsule Sizing'!$B$13,"Tight – test ("&TEXT('Capsule Sizing'!$D$30/120,"0%")&" full)","OK ("&TEXT('Capsule Sizing'!$D$30/120,"0%")&" full)"))) -> Too small | C10: =IF('Capsule Sizing'!$E$30/171>1,"Too small",IF('Capsule Sizing'!$D$30/150<'Capsule Sizing'!$B$12,"Looks < half ("&TEXT('Capsule Sizing'!$D$30/150,"0%")&")",IF('Capsule Sizing'!$E$30/150>'Capsule Sizing'!$B$13,"Tight – test ("&TEXT('Capsule Sizing'!$D$30/150,"0%")&" full)","OK ("&TEXT('Capsule Sizing'!$D$30/150,"0%")&" full)"))) -> Tight – test (96% full) | D10: =IF('Capsule Sizing'!$E$30/226>1,"Too small",IF('Capsule Sizing'!$D$30/200<'Capsule Sizing'!$B$12,"Looks < half ("&TEXT('Capsule Sizing'!$D$30/200,"0%")&")",IF('Capsule Sizing'!$E$30/200>'Capsule Sizing'!$B$13,"Tight – test ("&TEXT('Capsule Sizing'!$D$30/200,"0%")&" full)","OK ("&TEXT('Capsule Sizing'!$D$30/200,"0%")&" full)"))) -> OK (72% full) | E10: =IF('Capsule Sizing'!$E$30/275>1,"Too small",IF('Capsule Sizing'!$D$30/250<'Capsule Sizing'!$B$12,"Looks < half ("&TEXT('Capsule Sizing'!$D$30/250,"0%")&")",IF('Capsule Sizing'!$E$30/250>'Capsule Sizing'!$B$13,"Tight – test ("&TEXT('Capsule Sizing'!$D$30/250,"0%")&" full)","OK ("&TEXT('Capsule Sizing'!$D$30/250,"0%")&" full)"))) -> OK (58% full) | F10: 250cc
A11: New B – 90ct (if size 00) | B11: =IF('Capsule Sizing'!$E$29/135>1,"Too small",IF('Capsule Sizing'!$D$29/120<'Capsule Sizing'!$B$12,"Looks < half ("&TEXT('Capsule Sizing'!$D$29/120,"0%")&")",IF('Capsule Sizing'!$E$29/120>'Capsule Sizing'!$B$13,"Tight – test ("&TEXT('Capsule Sizing'!$D$29/120,"0%")&" full)","OK ("&TEXT('Capsule Sizing'!$D$29/120,"0%")&" full)"))) -> Too small | C11: =IF('Capsule Sizing'!$E$29/171>1,"Too small",IF('Capsule Sizing'!$D$29/150<'Capsule Sizing'!$B$12,"Looks < half ("&TEXT('Capsule Sizing'!$D$29/150,"0%")&")",IF('Capsule Sizing'!$E$29/150>'Capsule Sizing'!$B$13,"Tight – test ("&TEXT('Capsule Sizing'!$D$29/150,"0%")&" full)","OK ("&TEXT('Capsule Sizing'!$D$29/150,"0%")&" full)"))) -> Too small | D11: =IF('Capsule Sizing'!$E$29/226>1,"Too small",IF('Capsule Sizing'!$D$29/200<'Capsule Sizing'!$B$12,"Looks < half ("&TEXT('Capsule Sizing'!$D$29/200,"0%")&")",IF('Capsule Sizing'!$E$29/200>'Capsule Sizing'!$B$13,"Tight – test ("&TEXT('Capsule Sizing'!$D$29/200,"0%")&" full)","OK ("&TEXT('Capsule Sizing'!$D$29/200,"0%")&" full)"))) -> Tight – test (96% full) | E11: =IF('Capsule Sizing'!$E$29/275>1,"Too small",IF('Capsule Sizing'!$D$29/250<'Capsule Sizing'!$B$12,"Looks < half ("&TEXT('Capsule Sizing'!$D$29/250,"0%")&")",IF('Capsule Sizing'!$E$29/250>'Capsule Sizing'!$B$13,"Tight – test ("&TEXT('Capsule Sizing'!$D$29/250,"0%")&" full)","OK ("&TEXT('Capsule Sizing'!$D$29/250,"0%")&" full)"))) -> OK (77% full) | F11: 250cc
A12: Balance at ~40% is the same as today (owner accepted). Packers have shoulders, so they tend to look fuller than a straight-sided jar at the same fill. A packer line needs only 2 neck sizes (38 + 45-400) vs 3 for jars.
A14: 2. PACKER OPTIONS – landed cost (bottle + black PP cap + freight/brokerage)
A15: P1. REGULAR – TricorBraun 120 / 150 / 250cc, all three in ONE shipment (glass made in China → no surtax)
A16: Plan / SKU | B16: Supplier | C16: Item | D16: Size | E16: Currency | F16: Bottle price | G16: Cap price (per bottle needed) | H16: FX | I16: Goods (CAD/unit) | J16: Frosting (CAD/unit) | K16: Freight & one-time (CAD/unit) | L16: LANDED (CAD/unit) | M16: Landed if US-made (+50% on glass) | N16: Qty | O16: Total (CAD) | P16: Total if US-made (CAD) | Q16: Notes
A17: Balance – 30ct | B17: TricorBraun (US web store) | C17: 319293 120cc amber packer, 38-400 | D17: 120cc | E17: USD | F17: =677.34/Inputs!$B$5 -> 0.33867 | G17: =261/Inputs!$B$5 -> 0.1305 | H17: =IF(E17="USD",Inputs!$B$10,1) -> 1.424 | I17: =(F17+G17)*H17*(1+Inputs!$B$33) -> 0.66809808 | J17: 0 | K17: =(Inputs!$B$18*Inputs!$B$10+Inputs!$B$19)/Inputs!$B$8 -> 0.36686667 | L17: =I17+J17+K17 -> 1.0349647 | M17: =L17 -> 1.0349647 | N17: =Inputs!$B$5 -> 2000 | O17: =L17*N17 -> 2069.9295 | P17: =M17*N17 -> 2069.9295 | Q17: Live: 18 cases × $37.63 = $677.34 for 2,268 bottles (cheaper than 16 cases at $44.80). Cap 348629 black PP F-217, $261 per case of 2,900. Glass origin China (stated).
A18: New A – 60ct | B18: TricorBraun | C18: 319904 150cc amber packer, 45-400 | D18: 150cc | E18: USD | F18: 0.4167 | G18: =198.53/(Inputs!$B$6+Inputs!$B$7) -> 0.19853 | H18: =IF(E18="USD",Inputs!$B$10,1) -> 1.424 | I18: =(F18+G18)*H18*(1+Inputs!$B$33) -> 0.87608752 | J18: 0 | K18: =(Inputs!$B$18*Inputs!$B$10+Inputs!$B$19)/Inputs!$B$8 -> 0.36686667 | L18: =I18+J18+K18 -> 1.2429542 | M18: =L18 -> 1.2429542 | N18: =Inputs!$B$6 -> 500 | O18: =L18*N18 -> 621.47709 | P18: =M18*N18 -> 621.47709 | Q18: Live: $5.00/case of 12 at 18+ cases. 45-400 black caps come in 2,000-piece cases ($198.53) – shared with the 250cc. Origin China.
A19: New B – 90ct | B19: TricorBraun | C19: 319907 250cc amber packer, 45-400 | D19: 250cc | E19: USD | F19: 0.6117 | G19: =198.53/(Inputs!$B$6+Inputs!$B$7) -> 0.19853 | H19: =IF(E19="USD",Inputs!$B$10,1) -> 1.424 | I19: =(F19+G19)*H19*(1+Inputs!$B$33) -> 1.1537675 | J19: 0 | K19: =(Inputs!$B$18*Inputs!$B$10+Inputs!$B$19)/Inputs!$B$8 -> 0.36686667 | L19: =I19+J19+K19 -> 1.5206342 | M19: =L19 -> 1.5206342 | N19: =Inputs!$B$7 -> 500 | O19: =L19*N19 -> 760.31709 | P19: =M19*N19 -> 760.31709 | Q19: Live: $7.34/case of 12 at 18+ cases. Works for 90ct at size 0 or 00. Origin China.
A20: TOTAL | L20: =O20/Inputs!$B$8 -> 1.1505746 | O20: =SUM(O17:O19) -> 3451.7237 | P20: =SUM(P17:P19) -> 3451.7237
A22: P2. REGULAR – China packers for Balance + 60ct (one LCL) + TricorBraun 250cc for the 90ct (small US shipment)
A23: Plan / SKU | B23: Supplier | C23: Item | D23: Size | E23: Currency | F23: Bottle price | G23: Cap price (per bottle needed) | H23: FX | I23: Goods (CAD/unit) | J23: Frosting (CAD/unit) | K23: Freight & one-time (CAD/unit) | L23: LANDED (CAD/unit) | M23: Landed if US-made (+50% on glass) | N23: Qty | O23: Total (CAD) | P23: Total if US-made (CAD) | Q23: Notes
A24: Balance – 30ct | B24: China – Jinan Snail / NOVA / Advantrio (RFQ) | C24: 120cc amber packer, 38-400 | D24: 120cc | E24: USD | F24: 0.2 | G24: 0.04 | H24: =IF(E24="USD",Inputs!$B$10,1) -> 1.424 | I24: =(F24+G24)*H24*(1+Inputs!$B$33) -> 0.34176 | J24: 0 | K24: =(Inputs!$B$28+Inputs!$B$30)/(Inputs!$B$5+Inputs!$B$6) -> 0.664 | L24: =I24+J24+K24 -> 1.00576 | M24: =L24 -> 1.00576 | N24: =Inputs!$B$5 -> 2000 | O24: =L24*N24 -> 2011.52 | P24: =M24*N24 -> 2011.52 | Q24: Live made-in-china: Snail $0.20 at 1,000+; NOVA $0.058–0.062; Advantrio MOQ 500 (quote). Cap ESTIMATE US$0.04 (may be included).
A25: New A – 60ct | B25: China – Jinan Snail / NOVA / Advantrio (RFQ) | C25: 150cc amber packer, 45-400 | D25: 150cc | E25: USD | F25: 0.2 | G25: 0.04 | H25: =IF(E25="USD",Inputs!$B$10,1) -> 1.424 | I25: =(F25+G25)*H25*(1+Inputs!$B$33) -> 0.34176 | J25: 0 | K25: =(Inputs!$B$28+Inputs!$B$30)/(Inputs!$B$5+Inputs!$B$6) -> 0.664 | L25: =I25+J25+K25 -> 1.00576 | M25: =L25 -> 1.00576 | N25: =Inputs!$B$6 -> 500 | O25: =L25*N25 -> 502.88 | P25: =M25*N25 -> 502.88 | Q25: As above. Confirm 500 per size.
A26: New B – 90ct | B26: TricorBraun | C26: 319907 250cc, 45-400 | D26: 250cc | E26: USD | F26: 0.6117 | G26: 0.2 | H26: =IF(E26="USD",Inputs!$B$10,1) -> 1.424 | I26: =(F26+G26)*H26*(1+Inputs!$B$33) -> 1.1558608 | J26: 0 | K26: =(Inputs!$B$24*Inputs!$B$10+Inputs!$B$25)/Inputs!$B$7 -> 1.3892 | L26: =I26+J26+K26 -> 2.5450608 | M26: =L26 -> 2.5450608 | N26: =Inputs!$B$7 -> 500 | O26: =L26*N26 -> 1272.5304 | P26: =M26*N26 -> 1272.5304 | Q26: Small US shipment for the launch SKU.
A27: TOTAL | L27: =O27/Inputs!$B$8 -> 1.2623101 | O27: =SUM(O24:O26) -> 3786.9304 | P27: =SUM(P24:P26) -> 3786.9304
A29: P3. FROSTED – China frosted packers: Balance + 60ct by sea (LCL); 90ct by DDP AIR so it can launch first (~5–7 weeks incl. production)
A30: Plan / SKU | B30: Supplier | C30: Item | D30: Size | E30: Currency | F30: Bottle price | G30: Cap price (per bottle needed) | H30: FX | I30: Goods (CAD/unit) | J30: Frosting (CAD/unit) | K30: Freight & one-time (CAD/unit) | L30: LANDED (CAD/unit) | M30: Landed if US-made (+50% on glass) | N30: Qty | O30: Total (CAD) | P30: Total if US-made (CAD) | Q30: Notes
A31: Balance – 30ct | B31: China – Jinan Snail (frosted amber) | C31: 120cc frosted amber packer | D31: 120cc | E31: USD | F31: 0.3 | G31: 0.04 | H31: =IF(E31="USD",Inputs!$B$10,1) -> 1.424 | I31: =(F31+G31)*H31*(1+Inputs!$B$33) -> 0.48416 | J31: 0 | K31: =(Inputs!$B$28+Inputs!$B$30)/(Inputs!$B$5+Inputs!$B$6) -> 0.664 | L31: =I31+J31+K31 -> 1.14816 | M31: =L31 -> 1.14816 | N31: =Inputs!$B$5 -> 2000 | O31: =L31*N31 -> 2296.32 | P31: =M31*N31 -> 2296.32 | Q31: Live: Snail frosted amber $0.30 at 1,000–9,999. Confirm 500/size MOQ and whether cap is included.
A32: New A – 60ct | B32: China – Jinan Snail (frosted amber) | C32: 150cc frosted amber packer | D32: 150cc | E32: USD | F32: 0.3 | G32: 0.04 | H32: =IF(E32="USD",Inputs!$B$10,1) -> 1.424 | I32: =(F32+G32)*H32*(1+Inputs!$B$33) -> 0.48416 | J32: 0 | K32: =(Inputs!$B$28+Inputs!$B$30)/(Inputs!$B$5+Inputs!$B$6) -> 0.664 | L32: =I32+J32+K32 -> 1.14816 | M32: =L32 -> 1.14816 | N32: =Inputs!$B$6 -> 500 | O32: =L32*N32 -> 574.08 | P32: =M32*N32 -> 574.08 | Q32: As above.
A33: New B – 90ct | B33: China – Jinan Snail (frosted amber) | C33: 250cc frosted amber packer | D33: 250cc | E33: USD | F33: 0.3 | G33: 0.04 | H33: =IF(E33="USD",Inputs!$B$10,1) -> 1.424 | I33: =(F33+G33)*H33*(1+Inputs!$B$33) -> 0.48416 | J33: 0 | K33: =Inputs!$B$29/Inputs!$B$7 -> 1.74 | L33: =I33+J33+K33 -> 2.22416 | M33: =L33 -> 2.22416 | N33: =Inputs!$B$7 -> 500 | O33: =L33*N33 -> 1112.08 | P33: =M33*N33 -> 1112.08 | Q33: Shipped separately by DDP air (Inputs) for speed. North America has NO frosted amber packers in stock.
A34: TOTAL | L34: =O34/Inputs!$B$8 -> 1.3274933 | O34: =SUM(O31:O33) -> 3982.48 | P34: =SUM(P31:P33) -> 3982.48
A36: P4. FROSTED – China frosted packers for Balance + 60ct + TricorBraun 250cc spray-frosted in Canada for the 90ct
A37: Plan / SKU | B37: Supplier | C37: Item | D37: Size | E37: Currency | F37: Bottle price | G37: Cap price (per bottle needed) | H37: FX | I37: Goods (CAD/unit) | J37: Frosting (CAD/unit) | K37: Freight & one-time (CAD/unit) | L37: LANDED (CAD/unit) | M37: Landed if US-made (+50% on glass) | N37: Qty | O37: Total (CAD) | P37: Total if US-made (CAD) | Q37: Notes
A38: Balance – 30ct | B38: China – Jinan Snail (frosted amber) | C38: 120cc frosted amber packer | D38: 120cc | E38: USD | F38: 0.3 | G38: 0.04 | H38: =IF(E38="USD",Inputs!$B$10,1) -> 1.424 | I38: =(F38+G38)*H38*(1+Inputs!$B$33) -> 0.48416 | J38: 0 | K38: =(Inputs!$B$28+Inputs!$B$30)/(Inputs!$B$5+Inputs!$B$6) -> 0.664 | L38: =I38+J38+K38 -> 1.14816 | M38: =L38 -> 1.14816 | N38: =Inputs!$B$5 -> 2000 | O38: =L38*N38 -> 2296.32 | P38: =M38*N38 -> 2296.32 | Q38: As P3.
A39: New A – 60ct | B39: China – Jinan Snail (frosted amber) | C39: 150cc frosted amber packer | D39: 150cc | E39: USD | F39: 0.3 | G39: 0.04 | H39: =IF(E39="USD",Inputs!$B$10,1) -> 1.424 | I39: =(F39+G39)*H39*(1+Inputs!$B$33) -> 0.48416 | J39: 0 | K39: =(Inputs!$B$28+Inputs!$B$30)/(Inputs!$B$5+Inputs!$B$6) -> 0.664 | L39: =I39+J39+K39 -> 1.14816 | M39: =L39 -> 1.14816 | N39: =Inputs!$B$6 -> 500 | O39: =L39*N39 -> 574.08 | P39: =M39*N39 -> 574.08 | Q39: As P3.
A40: New B – 90ct | B40: TricorBraun + Stanpac spray frost | C40: 319907 250cc, 45-400 | D40: 250cc | E40: USD | F40: 0.6117 | G40: 0.2 | H40: =IF(E40="USD",Inputs!$B$10,1) -> 1.424 | I40: =(F40+G40)*H40*(1+Inputs!$B$33) -> 1.1558608 | J40: =Inputs!$B$37+(Inputs!$B$38+Inputs!$B$39)/Inputs!$B$7 -> 2.35 | K40: =(Inputs!$B$24*Inputs!$B$10+Inputs!$B$25)/Inputs!$B$7 -> 1.3892 | L40: =I40+J40+K40 -> 4.8950608 | M40: =L40 -> 4.8950608 | N40: =Inputs!$B$7 -> 500 | O40: =L40*N40 -> 2447.5304 | P40: =M40*N40 -> 2447.5304 | Q40: Spray-frost setup spread over just 500 bottles; frost finish may not match China's etched frost.
A41: TOTAL | L41: =O41/Inputs!$B$8 -> 1.7726435 | O41: =SUM(O38:O40) -> 5317.9304 | P41: =SUM(P38:P40) -> 5317.9304
A43: For comparison: STRAIGHT-SIDED frosted 90ct by DDP air from China (alternative to spray-frosting the 8 oz locally)
A44: Plan / SKU | B44: Supplier | C44: Item | D44: Size | E44: Currency | F44: Bottle price | G44: Cap price (per bottle needed) | H44: FX | I44: Goods (CAD/unit) | J44: Frosting (CAD/unit) | K44: Freight & one-time (CAD/unit) | L44: LANDED (CAD/unit) | M44: Landed if US-made (+50% on glass) | N44: Qty | O44: Total (CAD) | P44: Total if US-made (CAD) | Q44: Notes
A45: New B – 90ct | B45: China – Xuzhou Das (frosted 250 ml) | C45: Frosted amber straight-sided 250 ml | D45: 250 ml | E45: USD | F45: ='Frosted Finish – Top 3'!I9 -> 0.55 | G45: ='Frosted Finish – Top 3'!K9 -> 0.07 | H45: =IF(E45="USD",Inputs!$B$10,1) -> 1.424 | I45: =(F45+G45)*H45*(1+Inputs!$B$33) -> 0.88288 | J45: 0 | K45: =Inputs!$B$29/Inputs!$B$7 -> 1.74 | L45: =I45+J45+K45 -> 2.62288 | M45: =L45 -> 2.62288 | N45: =Inputs!$B$7 -> 500 | O45: =L45*N45 -> 1311.44 | P45: =M45*N45 -> 1311.44 | Q45: Same DDP-air route as P3, applied to straight-sided jars.
A46: TOTAL | O46: =SUM(O45:O45) -> 1311.44 | P46: =SUM(P45:P45) -> 1311.44
...

Sheet Product Links
A1: Product Links – every listing used in the pricing (click to open)
A2: Prices as captured on supplier websites, Oct 9, 2026. Prices change; confirm by quote.
A4: Supplier | B4: Product | C4: Price captured (Oct 9, 2026) | D4: Link
A5: CURRENT BOTTLE STYLE (amber wide-mouth packer) – regular
A6: TricorBraun (US store; glass made in China) | B6: 120cc packer 38-400 (319293) – Balance | C6: $37.63/case of 126 at 18+ cases | D6: https://www.tricorbraun.com/120-cc-amber-glass-round-packer-bottle-38-400-neck-finish.html
A7: TricorBraun | B7: 150cc packer 45-400 (319904) – 60ct | C7: $5.00/case of 12 at 18+ cases | D7: https://www.tricorbraun.com/150-cc-amber-glass-round-packer-bottle-45-400-neck-finish-319904.html
A8: TricorBraun | B8: 200cc packer 45-400 (319906) – 60ct fallback | C8: $6.42/case of 12 at 18+ cases | D8: https://www.tricorbraun.com/200-cc-amber-glass-round-packer-bottle-45-400-neck-finish-319906.html
A9: TricorBraun | B9: 250cc packer 45-400 (319907) – 90ct | C9: $7.34/case of 12 at 18+ cases | D9: https://www.tricorbraun.com/250-cc-amber-glass-round-packer-bottle-45-400-neck-finish.html
A10: TricorBraun | B10: 38-400 black PP cap, F-217 liner (348629) | C10: $261/case of 2,900 | D10: https://www.tricorbraun.com/38-400-black-pp-plastic-continuous-thread-closure-f-217-liner.html
A11: TricorBraun | B11: 45-400 black PP cap (HS-035 liner) | C11: ~$0.10–0.12 each in 2,000-pc case | D11: https://www.tricorbraun.com/45-400-black-pp-plastic-continuous-thread-lined-closure-hs-035-liner.html
A12: Containers & Packaging Supply | B12: 120cc packer G18118AM | C12: $0.39 full case | D12: https://www.containerandpackaging.com/products/glass-packer-bottle/g18118am/
A13: Containers & Packaging Supply | B13: 150cc packer G18117AM | C13: $0.43 full case | D13: https://www.containerandpackaging.com/products/glass-packer-bottle/g18117am/
A14: Containers & Packaging Supply | B14: 200cc packer G18119AM | C14: $0.47 full case | D14: https://www.containerandpackaging.com/products/glass-packer-bottle/g18119am/
A15: SKS Bottle | B15: 120cc pharmaceutical round (packer) 40110120.01M | C15: $45.31/96 on special; free UPS to Ontario on US$500+ | D15: https://www.sks-bottle.com/340c/fin7552.html
A16: Bottlestore | B16: 120cc amber packer | C16: $0.49 | D16: https://www.bottlestore.com/120cc-amber-wide-mouth-packer-round-glass-bottle-38-405-neck.html
A17: Bottlestore | B17: 150cc amber packer | C17: $0.42 | D17: https://www.bottlestore.com/150cc-amber-glass-wide-mouth-round-packer-bottle-round-45-400-neck.html
... A24: China – NOVA | B24: Amber packer 100–300ml with screw cap | C24: US$0.058–0.15 at 1,000 | D24: https://nuohuabaozhuang.en.made-in-china.com/product/OTpRyhFDrKYW/China-Wholesale-100ml-120ml-150ml-200ml-250ml-300ml-Amber-Wide-Mouth-Pharmaceutical-Grade-Glass-Bottle-with-Screw-Cap-for-Pills.html
A25: CURRENT BOTTLE STYLE – frosted (China only; none stocked in North America)
A26: China – Jinan Snail | B26: Frosted amber wide-mouth pill bottle | C26: US$0.30 at 1,000–9,999 | D26: https://snailglass.en.made-in-china.com/product/iJIRHfKEItpO/China-Wholesale-Amber-Frosted-Empty-Wide-Mouth-Glass-Bottle-Medicine-Pill-Bottles.html
A27: China – Jinan Snail | B27: Frosted 100–250ml health/capsule bottle | C27: US$0.30 | D27: https://snailglass.en.made-in-china.com/product/MxEYkSFGJRrb/China-100ml-120ml-150ml-250ml-Frosted-Glass-Health-Bottle-Capsule-with-Screw-Lid.html
A28: China – Advantrio | B28: Frosted amber 120ml pill bottle (MOQ 500) | C28: Quote | D28: https://advantriopackaging.en.made-in-china.com/product/RtXYDOaMZBUC/China-Wholesale-Empty-Wide-Mouth-Amber-Frosted-Glass-Jar-Pill-Capsule-Bottle-120ml.html
A29: China – Advantrio | B29: Frosted 200ml pill bottle (MOQ 500) | C29: Quote | D29: https://advantriopackaging.en.made-in-china.com/product/uASYIkaDhBRw/China-Luxury-Custom-Wide-Mouth-200ml-Frosted-Glass-Pill-Bottle-Jar-with-Lid.html
A30: STRAIGHT-SIDED JARS – regular
A31: Burch Bottle | B31: 4 oz amber straight-sided 58-400 (1SSA042GHG) | C31: $11.45/24 at 50–299 cs | D31: https://www.burchbottle.com/4oz-Amber-Straight-Sided-Jar-58-400
A32: Burch Bottle | B32: 6 oz amber straight-sided 63-400 (1SSA062GHG) | C32: $8.13/12 base | D32: https://www.burchbottle.com/6oz-Amber-Straight-Sided-Jar-63-400
A33: Burch Bottle | B33: 9 oz amber straight-sided 70-400 (1SSA092SGC) | C33: $5.29/12 at 40–175 cs | D33: https://www.burchbottle.com/9oz-Amber-Straight-Sided-Jar-70-400
A34: Burch Bottle | B34: 70-400 black PP cap PS22 (2BP0706MR) | C34: $0.30 | D34: https://www.burchbottle.com/70-400-Black-Polypropylene-RM-Ps22-Print-F217-Lined-Cap
A35: Fillmore Container | B35: 4 oz amber straight-sided (R04-30C) | C35: $12.95/24 | D35: https://www.fillmorecontainer.com/r04-30c-case24ct-1-12oz.html
A36: Fillmore Container | B36: 6 oz amber straight-sided (B06-30C) | C36: $7.99/12 | D36: https://www.fillmorecontainer.com/6-oz-amber-straight-sided-jar-case-of-12.html
A37: Fillmore Container | B37: 9 oz amber straight-sided (B09-30C) | C37: $6.35/12 | D37: https://www.fillmorecontainer.com/9-oz-amber-straight-sided-jar.html
A38: Containers & Packaging Supply | B38: 4 oz straight-sided G850AM | C38: $0.45 | D38: https://www.containerandpackaging.com/products/glass-straight-sided-jar/g850am/
A39: Containers & Packaging Supply | B39: 6 oz straight-sided G506AM | C39: $0.57 at 500 | D39: https://www.containerandpackaging.com/products/glass-straight-sided-jar/G506AM/
A40: SKS Bottle | B40: 8 oz amber straight-sided 70/400 (40530080.03S) – 90ct | C40: $31.68/36 | D40: https://www.sks-bottle.com/product/305037.html
A41: SKS Bottle | B41: 70/400 black cap, foam induction liner (2101-79) | C41: $159.60/760 | D41: https://www.sks-bottle.com/product/10710.html
A42: SKS Bottle | B42: Free shipping policy (Canada) | C42: US$500+ to Ontario | D42: https://www.sks-bottle.com/info/free_shipping.html
... A53: China – Xuzhou Selead | B53: Amber straight-sided 2/4/6/8 oz | C53: US$0.20–0.80, MOQ 5,000 | D53: https://xzselead.en.made-in-china.com/product/GamrQSoWqUcX/China-2oz-4oz-6oz-8oz-Amber-Glass-Jar-Straight-Sided-Glass-Candle-Jar-with-Metal-Lid-Clear-Amber-Glass-Storage-Jar-Candle-Holder.html
A54: STRAIGHT-SIDED JARS – frosted
A55: China – Xuzhou Das | B55: Frosted amber straight-sided 2/4/8 oz | C55: US$0.41 at 2,000+ | D55: https://daspacking.en.made-in-china.com/product/CdRGEuVYJmpN/China-Wholesale-2oz-4oz-8oz-60g-120g-250g-Frosted-Clear-Amber-Airtight-Straight-Sided-Round-Face-Cosmetic-Cream-Candle-Glass-Jar-and-Container-with-Lids.html
A56: The Bottle Depot (designer's link) | B56: 4 oz amber frosted straight-sided (frosted only up to 4 oz) | C56: $77.14/90 (sold out) | D56: https://thebottledepot.co/products/4-oz-amber-frosted-glass-straight-sided-round-jar-58-400-neck-finish
A57: Liquid Bottles | B57: 9 oz frosted amber straight-sided (out of stock) | C57: $1.57 | D57: https://www.liquidbottles.com/products/4738/9oz-Frosted-Amber-Glass-Jar-70-400-Neck-Finish-72cs
...

Sheet Summary
A1: Cocoon Supplements – Amber Straight-Sided Jar Sourcing
A2: Prepared by the procurement agent, updated Oct 9, 2026. Landed cost = jar + cap + freight, brokerage and one-time costs, in CAD per unit. Order: Balance 2,000 · new 60ct 500 · new 90ct 500 (edit on Inputs).
A3: ⚠ CONFIRMED: Canada charges a 50% surtax on US-MADE glass jars since Sept 8, 2026 (SOR/2026-186, tariff 7010.90.00). It applies by where the jar was made, not where it ships from. Ask US suppliers for country of origin. Both cases are shown below.
A5: Benchmark (bottle + lid, CAD/unit) | D5: =Inputs!$B$15 -> 3.44 | E5: Implied max from the previous manufacturer's $3.74 all-in quote minus the $0.30 label. Enter your current manufacturer's figure on Inputs.
A7: REGULAR (glossy) – Top 3 single-source options (all three SKUs from one supplier)
A8: Rank | B8: Option | C8: Jar sizes (30 / 60 / 90 ct) | D8: Landed CAD/unit | E8: Landed if US-made (surtax) | F8: Total all SKUs (CAD) | G8: Lead time | H8: Key pros | I8: Key risks / flags
A9: #1 | B9: Burch Bottle & Packaging (US) | C9: 4 oz / 6 oz / 9 oz | D9: ='Regular Finish – Top 3'!P10 -> 1.2893022 | E9: ='Regular Finish – Top 3'!S10 -> 1.6484667 | F9: ='Regular Finish – Top 3'!Q10 -> 3867.9067 | G9: ~1–2 wks + freight | H9: Lowest local cost; true 6 oz; deep stock; PS22 tamper-evident cap option | I9: Origin unknown (surtax risk); confirm 9 oz colour; USD/FX
A10: #2 | B10: Fillmore Container (US) | C10: 4 oz / 6 oz / 9 oz | D10: ='Regular Finish – Top 3'!P19 -> 1.3810711 | E10: ='Regular Finish – Top 3'!S19 -> 1.779 | F10: ='Regular Finish – Top 3'!Q19 -> 4143.2133 | G10: ~1–2 wks + freight | H10: Confirms shipping to Canada; same 4/6/9 line | I10: ~10% dearer than Burch; origin unknown (surtax risk)
A11: #3 | B11: China direct factory | C11: 120 / 180–190 / 250–270 ml | D11: ='Regular Finish – Top 3'!P28 -> 1.3286667 | E11: ='Regular Finish – Top 3'!S28 -> 1.3286667 | F11: ='Regular Finish – Top 3'!Q28 -> 3986 | G11: 10–13 weeks | H11: Cheapest; no surtax; duty Free | I11: Too slow for the urgent launch; RFQ + samples + QC needed; neck matching
A13: FROSTED / MATTE – Top 3 single-source options
A14: Rank | B14: Option | C14: Jar sizes (30 / 60 / 90 ct) | D14: Landed CAD/unit | E14: Landed if US-made (surtax) | F14: Total all SKUs (CAD) | G14: Lead time | H14: Key pros | I14: Key risks / flags
A15: #1 | B15: China direct factory (frosted) | C15: 120 / 180–190 / 250–270 ml | D15: ='Frosted Finish – Top 3'!P10 -> 1.4259733 | E15: ='Frosted Finish – Top 3'!S10 -> 1.4259733 | F15: ='Frosted Finish – Top 3'!Q10 -> 4277.92 | G15: 10–13 weeks | H15: Far cheapest; true etched frost; no surtax | I15: Too slow for the urgent launch; 180–190 ml frosted needs RFQ; QC risk
A16: #2 | B16: Burch + Canadian spray-frost | C16: 4 oz / 6 oz / 9 oz | D16: ='Frosted Finish – Top 3'!P19 -> 2.4893022 | E16: ='Frosted Finish – Top 3'!S19 -> 2.8484667 | F16: ='Frosted Finish – Top 3'!Q19 -> 7467.9067 | G16: ~3–6 weeks | H16: North American; true 6 oz; frost done in Canada | I16: Frost cost is an estimate; spray can scuff; surtax risk on jars
A17: #3 | B17: Fillmore + Canadian spray-frost | C17: 4 oz / 6 oz / 9 oz | D17: ='Frosted Finish – Top 3'!P28 -> 2.5810711 | E17: ='Frosted Finish – Top 3'!S28 -> 2.979 | F17: ='Frosted Finish – Top 3'!Q28 -> 7743.2133 | G17: ~3–6 weeks | H17: As #2; Fillmore ships to Canada | I17: Slightly dearer than #2; same risks
A19: SPLIT PLAN – one launch SKU bought locally now, the other two from China (details on 'Split Plan' sheet)
A20: Plan | B20: Description | D20: Total (CAD) | E20: Total if US-made | F20: vs all-local | G20: vs all-local (surtax)
A21: R-A | B21: ='Split Plan – Local vs China'!B6 -> Regular – all local (Burch; 90ct jar size guessed now) | D21: ='Split Plan – Local vs China'!C6 -> 3867.9067 | E21: ='Split Plan – Local vs China'!E6 -> 4945.4 | F21: ='Split Plan – Local vs China'!D6 -> 0 | G21: ='Split Plan – Local vs China'!F6 -> 0
A22: R-B1 | B22: ='Split Plan – Local vs China'!B7 -> Regular – FLEX: 6 oz local; 90ct is size 00 → 60ct launches | D22: ='Split Plan – Local vs China'!C7 -> 4693.94 | E22: ='Split Plan – Local vs China'!E7 -> 4935.13 | F22: ='Split Plan – Local vs China'!D7 -> 826.03333 | G22: ='Split Plan – Local vs China'!F7 -> -10.27
A23: R-FX0 | B23: ='Split Plan – Local vs China'!B8 -> Regular – FLEX: 6 oz local; 90ct is size 0 → 90ct launches | D23: ='Split Plan – Local vs China'!C8 -> 4716.66 | E23: ='Split Plan – Local vs China'!E8 -> 4957.85 | F23: ='Split Plan – Local vs China'!D8 -> 848.75333 | G23: ='Split Plan – Local vs China'!F8 -> 12.45
A24: R-B2 | B24: ='Split Plan – Local vs China'!B9 -> Regular – 90ct local (Burch 9 oz), rest China | D24: ='Split Plan – Local vs China'!C9 -> 4576.6333 | E24: ='Split Plan – Local vs China'!E9 -> 4733.57 | F24: ='Split Plan – Local vs China'!D9 -> 708.72667 | G24: ='Split Plan – Local vs China'!F9 -> -211.83
A25: R-B2c | B25: ='Split Plan – Local vs China'!B10 -> Regular – 90ct local (Richards, Canada), rest China | D25: ='Split Plan – Local vs China'!C10 -> 4217.12 | E25: ='Split Plan – Local vs China'!E10 -> 4217.12 | F25: ='Split Plan – Local vs China'!D10 -> 349.21333 | G25: ='Split Plan – Local vs China'!F10 -> -728.28
A26: F-A | B26: ='Split Plan – Local vs China'!B12 -> Frosted – all local (Burch + spray frost) | D26: ='Split Plan – Local vs China'!C12 -> 7467.9067 | E26: ='Split Plan – Local vs China'!E12 -> 8545.4 | F26: ='Split Plan – Local vs China'!D12 -> 0 | G26: ='Split Plan – Local vs China'!F12 -> 0
A27: F-B1 | B27: ='Split Plan – Local vs China'!B13 -> Frosted – FLEX: 6 oz local; 90ct is size 00 → 60ct launches | D27: ='Split Plan – Local vs China'!C13 -> 6075.42 | E27: ='Split Plan – Local vs China'!E13 -> 6316.61 | F27: ='Split Plan – Local vs China'!D13 -> -1392.4867 | G27: ='Split Plan – Local vs China'!F13 -> -2228.79
A28: F-FX0 | B28: ='Split Plan – Local vs China'!B14 -> Frosted – FLEX: 6 oz local; 90ct is size 0 → 90ct launches | D28: ='Split Plan – Local vs China'!C14 -> 6091.02 | E28: ='Split Plan – Local vs China'!E14 -> 6332.21 | F28: ='Split Plan – Local vs China'!D14 -> -1376.8867 | G28: ='Split Plan – Local vs China'!F14 -> -2213.19
A29: F-B2 | B29: ='Split Plan – Local vs China'!B15 -> Frosted – 90ct local (Burch 9 oz + spray frost), rest China | D29: ='Split Plan – Local vs China'!C15 -> 5950.9933 | E29: ='Split Plan – Local vs China'!E15 -> 6107.93 | F29: ='Split Plan – Local vs China'!D15 -> -1516.9133 | G29: ='Split Plan – Local vs China'!F15 -> -2437.47
A30: F-B2s | B30: ='Split Plan – Local vs China'!B16 -> Frosted – 90ct local (Liquid Bottles stock), rest China | D30: ='Split Plan – Local vs China'!C16 -> 5679.64 | E30: ='Split Plan – Local vs China'!E16 -> 6238.56 | F30: ='Split Plan – Local vs China'!D16 -> -1788.2667 | G30: ='Split Plan – Local vs China'!F16 -> -2306.84
A32: Recommendation (on current estimates – verify with quotes)
A33: FINAL RECOMMENDATION: see the 'Final Recommendation' tab (first tab).
A34: • Launch the 90ct androgen-balancing product first, in an 8 oz amber straight-sided jar bought locally (500 units; cheapest landed: SKS).
A35: • Balance (4 oz) + 60ct liver booster (6 oz): buy both from Burch in one shipment if Burch's jars aren't US-made; if they are (50% surtax), a China order is cheaper.
A36: • The tables above are the option analysis that led there.

Sheet Inputs
A1: Inputs & Assumptions
A2: Blue text on yellow = editable input. Every other sheet recalculates from these cells. Replace estimates with real quotes as they arrive.
A4: ORDER & BENCHMARK
A5: Units – Balance 30ct (4 oz) | B5: 2000 | C5: Owner: ~2,000 per run for the existing product. ASSUMED unchanged – edit if needed.
A6: Units – New 60ct liver booster (6 oz) | B6: 500 | C6: Owner: manufacturer can go as low as 500 per new SKU.
A7: Units – New 90ct androgen product (8 oz) | B7: 500 | C7: Owner: manufacturer can go as low as 500 per new SKU.
A8: Total units | B8: =$B$5+$B$6+$B$7 -> 3000 | C8: Sum of the three SKUs.
A9: Number of SKUs | B9: 3 | C9: Balance (30x size 0) + new 60ct + new 90ct.
A10: USD → CAD exchange rate | B10: 1.424 | C10: Bank of Canada rate, Oct 8, 2026. Update to your bank's rate on order day.
A11: Previous manufacturer – all-in packaging quote (CAD/unit) | B11: 3.74 | C11: From owner: bottle + lid + label + seal + bubble wrap. Currency assumed CAD.
A12: Estimated label cost (CAD/unit) | B12: 0.3 | C12: From owner's estimate.
A13: Implied MAX bottle + lid benchmark (CAD/unit) | B13: =$B$11-$B$12 -> 3.44 | C13: Upper bound only – the $3.74 also includes seal + bubble wrap, so true bottle + lid cost is lower.
A14: Current manufacturer bottle + lid cost (CAD/unit) – TO CONFIRM | C14: Fill in once your current manufacturer confirms. Leave blank to use the implied max above.
A15: Benchmark used in comparisons (CAD/unit) | B15: =IF($B$14="",$B$13,$B$14) -> 3.44 | C15: Uses the confirmed figure if entered, else the implied max.
A17: FREIGHT – ONE SHIPMENT FOR ALL THREE SKUs (~3,000 jars)
A18: US → Canada LTL, all SKUs in one shipment (~1 pallet, 900–1,100 lb) (USD) | B18: 650 | C18: ESTIMATE: Warp LTL index (Oct 9, 2026) – 500 lb US domestic pallet avg US$579 (middle half $390–694); cross-border costs more. Get a quote to your postal code.
A19: Customs brokerage, US import (CAD) | B19: 175 | C19: ESTIMATE: CAD 80–250. CPS includes brokerage in its online UPS rate.
A20: Domestic Canada freight, ~1 pallet (CAD) | B20: 300 | C20: ESTIMATE: Freightera Ontario pallet samples CAD 74–135 (2020–22) plus growth; Uline/Richards show cost at checkout.
A21: China → your door, LCL all three SKUs (~1.6 m³, ~550 kg) (CAD) | B21: 1250 | C21: ESTIMATE from live forwarder rates (Oct 2026): LCL US$150–220/m³ (1 m³ minimum) + CFS/THC + docs + brokerage (Clearit CAD 84.95 + 5%) + delivery.
A23: FREIGHT – SMALL / SPLIT SHIPMENTS
A24: US → Canada, ONE SKU of ~500 jars (200–360 lb; courier or partial pallet) (USD) | B24: 400 | C24: ESTIMATE: US$300–700. Exception: SKS ships free UPS Ground to Ontario on US$500+ orders (used on the Final tab).
A25: Customs brokerage, small US import (CAD) | B25: 125 | C25: ESTIMATE: CAD 80–250.
A26: Domestic Canada freight, ONE SKU of ~500 jars (CAD) | B26: 150 | C26: ESTIMATE: CAD 75–250.
A27: China → your door, LCL Balance 4 oz + 90ct 8 oz (~1.2 m³) (CAD) | B27: 1080 | C27: ESTIMATE from live rates (range CAD 550–1,600).
A28: China → your door, LCL Balance 4 oz + 60ct 6 oz (~1.0–1.3 m³, 350–450 kg) (CAD) | B28: 1060 | C28: ESTIMATE, mid case from live rates (range CAD 550–1,575). Balance alone ≈ CAD 1,015: adding the 60ct costs only ~CAD 35–110 because of the 1 m³ minimum.
A29: China → your door by DDP AIR, ONE SKU of ~500 bottles (~75–100 kg) (CAD) | B29: 870 | C29: ESTIMATE: ddpchain DDP air ~CAD 8.74/kg; 7–12 days transit after production. Lets a China-made launch SKU arrive in ~5–7 weeks.
A30: China samples + courier + wire fees + light QC (CAD, one-time) | B30: 600 | C30: ESTIMATE: CAD 250–900.
A32: DUTY & SURTAX
A33: Import duty, glass jars HS 7010.90 (MFN – applies to China and US) | B33: 0 | C33: VERIFIED: CBSA Customs Tariff T2026 ch. 70 (incl. T2026-2, Sept 1, 2026): 7010.90.00 MFN Free. No China surtax and no anti-dumping measure on glass jars.
A34: Canadian surtax on US-MADE glass jars (jar value only) | B34: 0.5 | C34: VERIFIED: United States Surtax Order (2026), SOR/2026-186, Schedule 3 (50%) lists 7010.90.00; in force Sept 8, 2026 (CBSA Customs Notice 26-23). Applies to goods ORIGINATING in the US, wherever shipped from. Plastic caps (3923.50) are not listed. A remission order may refund it for goods used in Canadian manufacturing – ask a broker; plan as if payable.
A36: FROSTING / DECORATION (estimates – quote required)
A37: North American spray-frost per jar (CAD) | B37: 0.45 | C37: ESTIMATE: CAD 0.30–0.60/jar. Stanpac (Smithville ON): spray frost, no minimum but economical at ~1 pallet, 3–5 weeks; no published price – quote required.
A38: North American spray-frost setup per SKU (CAD) | B38: 650 | C38: ESTIMATE: CAD 300–1,000 per SKU.
A39: Freight to/from decorator (CAD) | B39: 300 | C39: ESTIMATE.

Sheet Capsule Sizing
A1: Capsule Fill Sizing – which jar fits each SKU and looks at least half full?
A2: Volume needed depends on the capsules, not the container shape. A straight-sided jar needs the same cc as a packer bottle; it's just shorter and wider. In a straight-sided jar the fill line rises evenly, so 'pile %' ≈ how full it looks.
A4: Capsule specs
A5: Capsule size | B5: Closed length (mm) | C5: Outer diameter (mm) | D5: Envelope volume per capsule (cc) | E5: Pile volume per capsule – capsules only (cc) | F5: Space needed per capsule incl. headspace (cc)
A6: 0 | B6: 21.7 | C6: 7.65 | D6: =(PI()*(C6/2)^2*(B6-C6)+4/3*PI()*(C6/2)^3)/1000 -> 0.88020034 | E6: =D6/$B$10 -> 1.6003642 | F6: =E6*(1+$B$11) -> 1.8404189
A7: 00 | B7: 23.3 | C7: 8.53 | D7: =(PI()*(C7/2)^2*(B7-C7)+4/3*PI()*(C7/2)^3)/1000 -> 1.1690223 | E7: =D7/$B$10 -> 2.1254952 | F7: =E7*(1+$B$11) -> 2.4443194
A9: Assumptions
A10: Packing fraction (share of space filled by randomly poured capsules) | B10: 0.55 | C10: Random-packing estimate for capsule shapes. Calibrated to industry bottle charts (60x0 → 120cc, 90x0 → 175cc).
A11: Headspace allowance | B11: 0.15 | C11: Room for cotton/desiccant and so the cap closes without crushing capsules.
A12: Owner rule: minimum visible fill | B12: 0.5 | C12: From owner: no jar may look less than half full.
A13: Max space used before 'tight' | B13: 0.9
A15: Jar capacities (nominal)
A16: Jar | B16: Capacity (ml) | C16: Neck finish
A17: 4 oz | B17: 118 | C17: 58-400 | D17: Nominal (label) capacity. Brim-full capacity is typically 10–15% higher, so the 'space used' results are conservative and the 'looks full' results are slightly generous.
A18: 6 oz | B18: 177 | C18: 63-400
A19: 190 ml (China) | B19: 190 | C19: ~63 mm
A20: 8 oz | B20: 237 | C20: 70-400
A21: 250 ml (China) | B21: 250 | C21: ~70 mm
A22: 9 oz | B22: 266 | C22: 70-400
A24: How full will it LOOK? (capsule pile ÷ jar capacity; red = below the half-full rule)
A25: SKU / scenario | B25: Capsule size | C25: Count | D25: Pile (cc) | E25: Needed incl. headspace (cc) | F25: 4 oz | G25: 6 oz | H25: 190 ml (China) | I25: 8 oz | J25: 250 ml (China) | K25: 9 oz
A26: Balance – 30ct (current) | B26: 0 | C26: 30 | D26: =C26*INDEX($E$6:$E$7,MATCH(B26,$A$6:$A$7,0)) -> 48.010927 | E26: =C26*INDEX($F$6:$F$7,MATCH(B26,$A$6:$A$7,0)) -> 55.212567 | F26: =$D26/$B$17 -> 0.40687227 | G26: =$D26/$B$18 -> 0.27124818 | H26: =$D26/$B$19 -> 0.25268909 | I26: =$D26/$B$20 -> 0.20257775 | J26: =$D26/$B$21 -> 0.19204371 | K26: =$D26/$B$22 -> 0.18049221
A27: New A – 60ct (if size 00) | B27: 00 | C27: 60 | D27: =C27*INDEX($E$6:$E$7,MATCH(B27,$A$6:$A$7,0)) -> 127.52971 | E27: =C27*INDEX($F$6:$F$7,MATCH(B27,$A$6:$A$7,0)) -> 146.65917 | F27: =$D27/$B$17 -> 1.0807603 | G27: =$D27/$B$18 -> 0.72050684 | H27: =$D27/$B$19 -> 0.671209 | I27: =$D27/$B$20 -> 0.53810004 | J27: =$D27/$B$21 -> 0.51011884 | K27: =$D27/$B$22 -> 0.479435
A28: New A – 60ct (if size 0) | B28: 0 | C28: 60 | D28: =C28*INDEX($E$6:$E$7,MATCH(B28,$A$6:$A$7,0)) -> 96.021855 | E28: =C28*INDEX($F$6:$F$7,MATCH(B28,$A$6:$A$7,0)) -> 110.42513 | F28: =$D28/$B$17 -> 0.81374453 | G28: =$D28/$B$18 -> 0.54249635 | H28: =$D28/$B$19 -> 0.50537818 | I28: =$D28/$B$20 -> 0.40515551 | J28: =$D28/$B$21 -> 0.38408742 | K28: =$D28/$B$22 -> 0.36098442
A29: New B – 90ct (if size 00) | B29: 00 | C29: 90 | D29: =C29*INDEX($E$6:$E$7,MATCH(B29,$A$6:$A$7,0)) -> 191.29457 | E29: =C29*INDEX($F$6:$F$7,MATCH(B29,$A$6:$A$7,0)) -> 219.98875 | F29: =$D29/$B$17 -> 1.6211404 | G29: =$D29/$B$18 -> 1.0807603 | H29: =$D29/$B$19 -> 1.0068135 | I29: =$D29/$B$20 -> 0.80715007 | J29: =$D29/$B$21 -> 0.76517826 | K29: =$D29/$B$22 -> 0.7191525
A30: New B – 90ct (if size 0) | B30: 0 | C30: 90 | D30: =C30*INDEX($E$6:$E$7,MATCH(B30,$A$6:$A$7,0)) -> 144.03278 | E30: =C30*INDEX($F$6:$F$7,MATCH(B30,$A$6:$A$7,0)) -> 165.6377 | F30: =$D30/$B$17 -> 1.2206168 | G30: =$D30/$B$18 -> 0.81374453 | H30: =$D30/$B$19 -> 0.75806727 | I30: =$D30/$B$20 -> 0.60773326 | J30: =$D30/$B$21 -> 0.57613113 | K30: =$D30/$B$22 -> 0.54147662
A32: Verdict per jar (OK · Tight – test · Looks < half · Too small)
A33: SKU / scenario | B33: Capsule size | C33: Count | D33: Pile (cc) | E33: Needed incl. headspace (cc) | F33: 4 oz | G33: 6 oz | H33: 190 ml (China) | I33: 8 oz | J33: 250 ml (China) | K33: 9 oz
A34: Balance – 30ct (current) | B34: 0 | C34: 30 | D34: =C34*INDEX($E$6:$E$7,MATCH(B34,$A$6:$A$7,0)) -> 48.010927 | E34: =C34*INDEX($F$6:$F$7,MATCH(B34,$A$6:$A$7,0)) -> 55.212567 | F34: =IF($E34/$B$17>1,"Too small",IF($D34/$B$17<$B$12,"Looks < half",IF($E34/$B$17>$B$13,"Tight – test","OK"))) -> Looks < half | G34: =IF($E34/$B$18>1,"Too small",IF($D34/$B$18<$B$12,"Looks < half",IF($E34/$B$18>$B$13,"Tight – test","OK"))) -> Looks < half | H34: =IF($E34/$B$19>1,"Too small",IF($D34/$B$19<$B$12,"Looks < half",IF($E34/$B$19>$B$13,"Tight – test","OK"))) -> Looks < half | I34: =IF($E34/$B$20>1,"Too small",IF($D34/$B$20<$B$12,"Looks < half",IF($E34/$B$20>$B$13,"Tight – test","OK"))) -> Looks < half | J34: =IF($E34/$B$21>1,"Too small",IF($D34/$B$21<$B$12,"Looks < half",IF($E34/$B$21>$B$13,"Tight – test","OK"))) -> Looks < half | K34: =IF($E34/$B$22>1,"Too small",IF($D34/$B$22<$B$12,"Looks < half",IF($E34/$B$22>$B$13,"Tight – test","OK"))) -> Looks < half
A35: New A – 60ct (if size 00) | B35: 00 | C35: 60 | D35: =C35*INDEX($E$6:$E$7,MATCH(B35,$A$6:$A$7,0)) -> 127.52971 | E35: =C35*INDEX($F$6:$F$7,MATCH(B35,$A$6:$A$7,0)) -> 146.65917 | F35: =IF($E35/$B$17>1,"Too small",IF($D35/$B$17<$B$12,"Looks < half",IF($E35/$B$17>$B$13,"Tight – test","OK"))) -> Too small | G35: =IF($E35/$B$18>1,"Too small",IF($D35/$B$18<$B$12,"Looks < half",IF($E35/$B$18>$B$13,"Tight – test","OK"))) -> OK | H35: =IF($E35/$B$19>1,"Too small",IF($D35/$B$19<$B$12,"Looks < half",IF($E35/$B$19>$B$13,"Tight – test","OK"))) -> OK | I35: =IF($E35/$B$20>1,"Too small",IF($D35/$B$20<$B$12,"Looks < half",IF($E35/$B$20>$B$13,"Tight – test","OK"))) -> OK | J35: =IF($E35/$B$21>1,"Too small",IF($D35/$B$21<$B$12,"Looks < half",IF($E35/$B$21>$B$13,"Tight – test","OK"))) -> OK | K35: =IF($E35/$B$22>1,"Too small",IF($D35/$B$22<$B$12,"Looks < half",IF($E35/$B$22>$B$13,"Tight – test","OK"))) -> Looks < half
A36: New A – 60ct (if size 0) | B36: 0 | C36: 60 | D36: =C36*INDEX($E$6:$E$7,MATCH(B36,$A$6:$A$7,0)) -> 96.021855 | E36: =C36*INDEX($F$6:$F$7,MATCH(B36,$A$6:$A$7,0)) -> 110.42513 | F36: =IF($E36/$B$17>1,"Too small",IF($D36/$B$17<$B$12,"Looks < half",IF($E36/$B$17>$B$13,"Tight – test","OK"))) -> Tight – test | G36: =IF($E36/$B$18>1,"Too small",IF($D36/$B$18<$B$12,"Looks < half",IF($E36/$B$18>$B$13,"Tight – test","OK"))) -> OK | H36: =IF($E36/$B$19>1,"Too small",IF($D36/$B$19<$B$12,"Looks < half",IF($E36/$B$19>$B$13,"Tight – test","OK"))) -> OK | I36: =IF($E36/$B$20>1,"Too small",IF($D36/$B$20<$B$12,"Looks < half",IF($E36/$B$20>$B$13,"Tight – test","OK"))) -> Looks < half | J36: =IF($E36/$B$21>1,"Too small",IF($D36/$B$21<$B$12,"Looks < half",IF($E36/$B$21>$B$13,"Tight – test","OK"))) -> Looks < half | K36: =IF($E36/$B$22>1,"Too small",IF($D36/$B$22<$B$12,"Looks < half",IF($E36/$B$22>$B$13,"Tight – test","OK"))) -> Looks < half
